Workbook
Name Slicer_BRAND: #N/A
Name Slicer_BRAND1: #N/A
Name Slicer_MANUFACTURER2: #N/A
Name Slicer_PACKAGE_SIZE1: #N/A
Name Slicer_PACKAGE_SIZE2: #N/A
Name Slicer_Package_Type: #N/A
Name Slicer_PACKAGE_TYPE1: #N/A
Name Slicer_PROTECTION___CARE: #N/A
Name Slicer_Protection_Care: #N/A

Sheet RawData
A1: BABY CARE PRODUCT ANALYSIS (using Excel) | F1: Value (in 1000 $) | I1: Volume (in 1000)
F2: 2022 | G2: 2023 | H2: YTD 24 | I2: 2022 | J2: 2023 | K2: YTD 24
A3: FreshClean | B3: BRAND | C3: PACKAGE TYPE | D3: PROTECTION / CARE | E3: PACKAGE SIZE | F3: 31416.343 | G3: 32432.398 | H3: 17382.01 | I3: 1194607.9 | J3: 1188013.2 | K3: 600950.98
A4: Nova Garbagnate | B4: MANUFACTURER | F4: 1.935 | G4: 0.624 | I4: 24.8229 | J4: 9.4086
A5: BABY 2000 (Nova Garbagnate) | B5: BRAND | F5: 1.935 | G5: 0.624 | I5: 24.8229 | J5: 9.4086
A6: BABY2000 CAMOMILLA W 20 BAG ABA SRL | B6: ITEM | C6: BAGS | D6: WITHOUT EXTRA PROTECTCARE INDICATION | E6: 20 | F6: 1.935 | G6: 0.624 | I6: 24.8229 | J6: 9.4086
A7: BeneCare | B7: MANUFACTURER | F7: 0.0109 | I7: 0.16
A8: BAMBO (BeneCare) | B8: BRAND | F8: 0.0109 | I8: 0.16
A9: BAMBO NATURE W 10 BAG | B9: ITEM | C9: BAGS | D9: WITHOUT EXTRA PROTECTCARE INDICATION | E9: 10
A10: BAMBO NATURE W 50 BAG | B10: ITEM | C10: BAGS | D10: WITHOUT EXTRA PROTECTCARE INDICATION | E10: 50
A11: BAMBO NATURE 0%PERFUME W 80 BAG | B11: ITEM | C11: BAGS | D11: WITHOUT EXTRA PROTECTCARE INDICATION | E11: 80
A12: BAMBO NATURE W 80 BAG KAPAK | B12: ITEM | C12: BAGS | D12: WITHOUT EXTRA PROTECTCARE INDICATION | E12: 80 | F12: 0.0109 | I12: 0.16
A13: VigaLife | B13: MANUFACTURER | F13: 3341.5013 | G13: 3428.0437 | H13: 1852.1969 | I13: 125970.25 | J13: 127615.61 | K13: 64977.618
A14: BABY CREMA (VigaLife) | B14: BRAND | F14: 3341.5013 | G14: 3428.0437 | H14: 1852.1969 | I14: 125970.25 | J14: 127615.61 | K14: 64977.618
A15: BABY CREMA PLAY TIME CAMOMILE W 100 PINK | B15: ITEM | C15: BAGS | D15: PH BALANCED | E15: 100 | F15: 81.4674 | G15: 92.903 | H15: 52.5119 | I15: 2980.7043 | J15: 3415.3554 | K15: 1823.0734
A16: BABYCREMA PLAYTIME CAMOMILE W 100 ORANGE | B16: ITEM | C16: BAGS | D16: PH BALANCED | E16: 100 | F16: 165.228 | G16: 172.6843 | H16: 91.1357 | I16: 5930.9056 | J16: 6183.6273 | K16: 3125.7987
A17: BABY CREMA CAMOMIL W 120 BAG KAPAK | B17: ITEM | C17: BAGS | D17: PH BALANCED | E17: 120 | F17: 842.8724 | G17: 745.3358 | H17: 366.9589 | I17: 38888.54 | J17: 31985 | K17: 14135.173
A18: BABY CREMA ALOE 15 BAG | B18: ITEM | C18: BAGS | D18: WITHOUT EXTRA PROTECTCARE INDICATION | E18: 15 | F18: 12.7748 | G18: 10.866 | H18: 6.7743 | I18: 151.2668 | J18: 127.1868 | K18: 77.4594
A19: BABY CREMA CAMOMIL W 15 BAG | B19: ITEM | C19: BAGS | D19: WITHOUT EXTRA PROTECTCARE INDICATION | E19: 15 | F19: 20.0553 | G19: 17.8361 | H19: 11.1871 | I19: 231.0878 | J19: 217.7118 | K19: 141.008
A20: BABY CREMA PH5.5 W 3X15/1FR BAG &&& | B20: ITEM | C20: BAGS | D20: PH BALANCED | E20: 15 | F20: 1.2461 | G20: 7.7651 | H20: 2.2378 | I20: 20.9609 | J20: 127.6666 | K20: 33.571
A21: BABY CREMA WATER 99% W 15 BAG | B21: ITEM | C21: BAGS | D21: ALCOHOL FREE | E21: 15 | F21: 9.6472 | G21: 10.7577 | H21: 7.0723 | I21: 112.2061 | J21: 131.0528 | K21: 85.7198
A22: BABY CREMA CAMOMIL W 40 BAG | B22: ITEM | C22: BAGS | D22: WITHOUT EXTRA PROTECTCARE INDICATION | E22: 40 | F22: 0.1235 | I22: 2.28
A23: BABY CREMA COTTON&PANTENOL W 4X56 BAG | B23: ITEM | C23: BAGS | D23: PH BALANCED | E23: 56 | H23: 7.1128 | K23: 247.099
A24: BABY CREMA COTTON&PANTENOL W 56 BAG | B24: ITEM | C24: BAGS | D24: PH BALANCED | E24: 56 | F24: 0.1831 | G24: 0.1116 | H24: 0.387 | I24: 5.8885 | J24: 3.791 | K24: 14.3827
A25: BABY CREMA ALOE 64 BAG | B25: ITEM | C25: BAGS | D25: WITHOUT EXTRA PROTECTCARE INDICATION | E25: 64 | F25: 1.8939 | H25: 0.2252 | I25: 49.9726 | K25: 6.9501
A26: BABY CREMA CAMOMIL W 64 BAG | B26: ITEM | C26: BAGS | D26: WITHOUT EXTRA PROTECTCARE INDICATION | E26: 64 | F26: 1.3515 | G26: 0.0017 | I26: 37.3226 | J26: 0.064
A27: BABY CREMA PLAY TIME CAMOMIL W 64 BAG | B27: ITEM | C27: BAGS | D27: PH BALANCED | E27: 64 | F27: 5.8978 | G27: 0.1087 | I27: 169.5808 | J27: 3.3823
A28: BABYCREMA CAMOMIL W 4X64 BAG SUPERTSENA | B28: ITEM | C28: BAGS | D28: ALCOHOL FREE | E28: 64 | F28: 0.6967 | G28: 28.3929 | H28: 2.1978 | I28: 25.6063 | J28: 1226.3662 | K28: 96.4388
A29: BABY CREMA ALOE&ALMOND OIL W 72 BAG | B29: ITEM | C29: BAGS | D29: WITHOUT EXTRA PROTECTCARE INDICATION | E29: 72 | F29: 117.6534 | G29: 68.1177 | H29: 28.3499 | I29: 3055.9406 | J29: 1781.8513 | K29: 711.0772
A30: BABY CREMA CAMOMIL&ALMOND W 72 BAG | B30: ITEM | C30: BAGS | D30: WITHOUT EXTRA PROTECTCARE INDICATION | E30: 72 | F30: 38.6778 | G30: 31.4983 | H30: 9.7551 | I30: 954.1122 | J30: 803.2852 | K30: 236.1983
A31: BABY CREMA COTTON W 2X72BAG50%OT TS.VTOR | B31: ITEM | C31: BAGS | D31: PH BALANCED | E31: 72 | F31: 0.0612 | I31: 1.6046
A32: BABY CREMA COTTON&PANTENOL W 72 BAG | B32: ITEM | C32: BAGS | D32: PH BALANCED | E32: 72 | F32: 36.5218 | G32: 5.1192 | H32: 1.1213 | I32: 1199.5277 | J32: 135.3687 | K32: 30.5544
A33: BABY CREMA NEVEN PH5.5 W 72 BAG | B33: ITEM | C33: BAGS | D33: PH BALANCED | E33: 72 | F33: 21.9583 | G33: 39.4671 | H33: 10.7844 | I33: 726.314 | J33: 1508.4714 | K33: 314.5264
A34: BABY CREMA SMRADLIKA PH5.5 W 72 BAG | B34: ITEM | C34: BAGS | D34: PH BALANCED | E34: 72 | F34: 27.9836 | G34: 162.4105 | H34: 103.168 | I34: 928.8153 | J34: 5484.9445 | K34: 3446.0195
A35: BABY CREMA WATER 99% W 72 BAG | B35: ITEM | C35: BAGS | D35: WITHOUT EXTRA PROTECTCARE INDICATION | E35: 72 | F35: 221.1702 | G35: 159.9896 | H35: 77.8656 | I35: 6715.8593 | J35: 4333.2688 | K35: 2035.5381
A36: BABYCREMA CAMOMILE W 2X72BAG50%OTTS.VTOR | B36: ITEM | C36: BAGS | D36: PH BALANCED | E36: 72 | F36: 6.4487 | G36: 1.6864 | I36: 194.6519 | J36: 50.7003
A37: BABYCREMA COTTON&PANTENOL W 3X72/1FR BAG | B37: ITEM | C37: BAGS | D37: PH BALANCED | E37: 72
A38: BABYCREMA PLAYTIME CAMOMIL W 72 BAG KAPA | B38: ITEM | C38: BAGS | D38: PH BALANCED | E38: 72 | F38: 1663.8369 | G38: 1815.6597 | H38: 1049.2486 | I38: 62012.673 | J38: 68679.966 | K38: 37856.882
A39: BABY CREMA ALOE W 80 BAG | B39: ITEM | C39: BAGS | D39: WITHOUT EXTRA PROTECTCARE INDICATION | E39: 80 | F39: 1.7698 | G39: 0.3617 | H39: 0.2081 | I39: 50.2205 | J39: 12.0681 | K39: 5.4643
A40: BABY CREMA CAMOMIL W 80 BAG | B40: ITEM | C40: BAGS | D40: WITHOUT EXTRA PROTECTCARE INDICATION | E40: 80 | F40: 61.9819 | G40: 56.9702 | H40: 23.8948 | I40: 1524.2099 | J40: 1404.4859 | K40: 554.6842
...

Sheet BabycareClean
A8: Product | B8: BRAND | C8: PACKAGE TYPE | D8: PROTECTION / CARE | E8: PACKAGE SIZE | F8: 2022 | G8: 2023 | H8: YTD 24 | I8: Volume 2022 | J8: Volume 2023 | K8: Volume YTD 2024 | L8: Total Value
A9: BABY CARE PRODUCT ANALYSIS (By Excel) | F9: 31416.343 | G9: 32432.398 | H9: 17382.01 | I9: 1194607.9 | J9: 1188013.2 | K9: 600950.98 | L9: =SUM(BabycareRaw[[#This Row],[2022]:[YTD 24]]) -> 81230.751
A10: Nova Garbagnate | B10: MANUFACTURER | F10: 1.935 | G10: 0.624 | H10: 0 | I10: 24.8229 | J10: 9.4086 | K10: 0 | L10: =SUM(BabycareRaw[[#This Row],[2022]:[YTD 24]]) -> 2.559
A11: BABY 2000 (Nova Garbagnate) | B11: BRAND | F11: 1.935 | G11: 0.624 | H11: 0 | I11: 24.8229 | J11: 9.4086 | K11: 0 | L11: =SUM(BabycareRaw[[#This Row],[2022]:[YTD 24]]) -> 2.559
A12: BABY2000 CAMOMILLA W 20 BAG ABA SRL | B12: ITEM | C12: BAGS | D12: WITHOUT EXTRA PROTECTCARE INDICATION | E12: 20 | F12: 1.94 | G12: 0.624 | H12: 0 | I12: 24.8229 | J12: 9.4086 | K12: 0 | L12: =SUM(BabycareRaw[[#This Row],[2022]:[YTD 24]]) -> 2.564
A13: BeneCare | B13: MANUFACTURER | F13: 0.0109 | G13: 0 | H13: 0 | I13: 0.16 | J13: 0 | K13: 0 | L13: =SUM(BabycareRaw[[#This Row],[2022]:[YTD 24]]) -> 0.0109
A14: BAMBO (BeneCare) | B14: BRAND | F14: 0.0109 | G14: 0 | H14: 0 | I14: 0.16 | J14: 0 | K14: 0 | L14: =SUM(BabycareRaw[[#This Row],[2022]:[YTD 24]]) -> 0.0109
A15: BAMBO NATURE W 10 BAG | B15: ITEM | C15: BAGS | D15: WITHOUT EXTRA PROTECTCARE INDICATION | E15: 10 | F15: 0 | G15: 0 | H15: 0 | I15: 0 | J15: 0 | K15: 0 | L15: =SUM(BabycareRaw[[#This Row],[2022]:[YTD 24]]) -> 0
A16: BAMBO NATURE W 50 BAG | B16: ITEM | C16: BAGS | D16: WITHOUT EXTRA PROTECTCARE INDICATION | E16: 50 | F16: 0 | G16: 0 | H16: 0 | I16: 0 | J16: 0 | K16: 0 | L16: =SUM(BabycareRaw[[#This Row],[2022]:[YTD 24]]) -> 0
A17: BAMBO NATURE 0%PERFUME W 80 BAG | B17: ITEM | C17: BAGS | D17: WITHOUT EXTRA PROTECTCARE INDICATION | E17: 80 | F17: 0 | G17: 0 | H17: 0 | I17: 0 | J17: 0 | K17: 0 | L17: =SUM(BabycareRaw[[#This Row],[2022]:[YTD 24]]) -> 0
A18: BAMBO NATURE W 80 BAG KAPAK | B18: ITEM | C18: BAGS | D18: WITHOUT EXTRA PROTECTCARE INDICATION | E18: 80 | F18: 0.0109 | G18: 0 | H18: 0 | I18: 0.16 | J18: 0 | K18: 0 | L18: =SUM(BabycareRaw[[#This Row],[2022]:[YTD 24]]) -> 0.0109
A19: VigaLife | B19: MANUFACTURER | F19: 3341.5013 | G19: 3428.0437 | H19: 1852.1969 | I19: 125970.25 | J19: 127615.61 | K19: 64977.618 | L19: =SUM(BabycareRaw[[#This Row],[2022]:[YTD 24]]) -> 8621.7419
A20: BABY CREMA (VigaLife) | B20: BRAND | F20: 3341.5013 | G20: 3428.0437 | H20: 1852.1969 | I20: 125970.25 | J20: 127615.61 | K20: 64977.618 | L20: =SUM(BabycareRaw[[#This Row],[2022]:[YTD 24]]) -> 8621.7419
A21: BABY CREMA PLAY TIME CAMOMILE W 100 PINK | B21: ITEM | C21: BAGS | D21: PH BALANCED | E21: 100 | F21: 81.4674 | G21: 92.903 | H21: 52.5119 | I21: 2980.7043 | J21: 3415.3554 | K21: 1823.0734 | L21: =SUM(BabycareRaw[[#This Row],[2022]:[YTD 24]]) -> 226.8823
A22: BABYCREMA PLAYTIME CAMOMILE W 100 ORANGE | B22: ITEM | C22: BAGS | D22: PH BALANCED | E22: 100 | F22: 165.228 | G22: 172.6843 | H22: 91.1357 | I22: 5930.9056 | J22: 6183.6273 | K22: 3125.7987 | L22: =SUM(BabycareRaw[[#This Row],[2022]:[YTD 24]]) -> 429.048
A23: BABY CREMA CAMOMIL W 120 BAG KAPAK | B23: ITEM | C23: BAGS | D23: PH BALANCED | E23: 120 | F23: 842.8724 | G23: 745.3358 | H23: 366.9589 | I23: 38888.54 | J23: 31985 | K23: 14135.173 | L23: =SUM(BabycareRaw[[#This Row],[2022]:[YTD 24]]) -> 1955.1671
A24: BABY CREMA ALOE 15 BAG | B24: ITEM | C24: BAGS | D24: WITHOUT EXTRA PROTECTCARE INDICATION | E24: 15 | F24: 12.7748 | G24: 10.866 | H24: 6.7743 | I24: 151.2668 | J24: 127.1868 | K24: 77.4594 | L24: =SUM(BabycareRaw[[#This Row],[2022]:[YTD 24]]) -> 30.4151
A25: BABY CREMA CAMOMIL W 15 BAG | B25: ITEM | C25: BAGS | D25: WITHOUT EXTRA PROTECTCARE INDICATION | E25: 15 | F25: 20.0553 | G25: 17.8361 | H25: 11.1871 | I25: 231.0878 | J25: 217.7118 | K25: 141.008 | L25: =SUM(BabycareRaw[[#This Row],[2022]:[YTD 24]]) -> 49.0785
A26: BABY CREMA PH5.5 W 3X15/1FR BAG &&& | B26: ITEM | C26: BAGS | D26: PH BALANCED | E26: 15 | F26: 1.2461 | G26: 7.7651 | H26: 2.2378 | I26: 20.9609 | J26: 127.6666 | K26: 33.571 | L26: =SUM(BabycareRaw[[#This Row],[2022]:[YTD 24]]) -> 11.249
A27: BABY CREMA WATER 99% W 15 BAG | B27: ITEM | C27: BAGS | D27: ALCOHOL FREE | E27: 15 | F27: 9.6472 | G27: 10.7577 | H27: 7.0723 | I27: 112.2061 | J27: 131.0528 | K27: 85.7198 | L27: =SUM(BabycareRaw[[#This Row],[2022]:[YTD 24]]) -> 27.4772
A28: BABY CREMA CAMOMIL W 40 BAG | B28: ITEM | C28: BAGS | D28: WITHOUT EXTRA PROTECTCARE INDICATION | E28: 40 | F28: 0.1235 | G28: 0 | H28: 0 | I28: 2.28 | J28: 0 | K28: 0 | L28: =SUM(BabycareRaw[[#This Row],[2022]:[YTD 24]]) -> 0.1235
A29: BABY CREMA COTTON&PANTENOL W 4X56 BAG | B29: ITEM | C29: BAGS | D29: PH BALANCED | E29: 56 | F29: 0 | G29: 0 | H29: 7.1128 | I29: 0 | J29: 0 | K29: 247.099 | L29: =SUM(BabycareRaw[[#This Row],[2022]:[YTD 24]]) -> 7.1128
A30: BABY CREMA COTTON&PANTENOL W 56 BAG | B30: ITEM | C30: BAGS | D30: PH BALANCED | E30: 56 | F30: 0.1831 | G30: 0.1116 | H30: 0.387 | I30: 5.8885 | J30: 3.791 | K30: 14.3827 | L30: =SUM(BabycareRaw[[#This Row],[2022]:[YTD 24]]) -> 0.6817
A31: BABY CREMA ALOE 64 BAG | B31: ITEM | C31: BAGS | D31: WITHOUT EXTRA PROTECTCARE INDICATION | E31: 64 | F31: 1.8939 | G31: 0 | H31: 0.2252 | I31: 49.9726 | J31: 0 | K31: 6.9501 | L31: =SUM(BabycareRaw[[#This Row],[2022]:[YTD 24]]) -> 2.1191
A32: BABY CREMA CAMOMIL W 64 BAG | B32: ITEM | C32: BAGS | D32: WITHOUT EXTRA PROTECTCARE INDICATION | E32: 64 | F32: 1.3515 | G32: 0.0017 | H32: 0 | I32: 37.3226 | J32: 0.064 | K32: 0 | L32: =SUM(BabycareRaw[[#This Row],[2022]:[YTD 24]]) -> 1.3532
... A46: BABY CREMA CAMOMIL W 80 BAG | B46: ITEM | C46: BAGS | D46: WITHOUT EXTRA PROTECTCARE INDICATION | E46: 80 | F46: 61.9819 | G46: 56.9702 | H46: 23.8948 | I46: 1524.2099 | J46: 1404.4859 | K46: 554.6842 | L46: =SUM(BabycareRaw[[#This Row],[2022]:[YTD 24]]) -> 142.8469
A47: Intelligent Initiative | B47: MANUFACTURER | F47: 511.7809 | G47: 507.3048 | H47: 295.7138 | I47: 23199.702 | J47: 21680.539 | K47: 11434.484 | L47: =SUM(BabycareRaw[[#This Row],[2022]:[YTD 24]]) -> 1314.7995
A48: LINDY (Intelligent Initiative) | B48: BRAND | F48: 511.7809 | G48: 507.3048 | H48: 295.7138 | I48: 23199.702 | J48: 21680.539 | K48: 11434.484 | L48: =SUM(BabycareRaw[[#This Row],[2022]:[YTD 24]]) -> 1314.7995
A49: LINDY VITAMIN E PH5.5 W 120 BAG | B49: ITEM | C49: BAGS | D49: PH BALANCED | E49: 120 | F49: 78.228 | G49: 99.0305 | H49: 56.6741 | I49: 4816.5708 | J49: 5822.6244 | K49: 2923.4183 | L49: =SUM(BabycareRaw[[#This Row],[2022]:[YTD 24]]) -> 233.9326
A50: LINDY ALOE VERA&VIT E W 64 BAG | B50: ITEM | C50: BAGS | D50: WITHOUT EXTRA PROTECTCARE INDICATION | E50: 64 | F50: 11.11 | G50: 8.9544 | H50: 2.2329 | I50: 523.1682 | J50: 387.3223 | K50: 84.4284 | L50: =SUM(BabycareRaw[[#This Row],[2022]:[YTD 24]]) -> 22.2973
A51: LINDY ALOE VERA&VIT E W 64 BAG KAPAK | B51: ITEM | C51: BAGS | D51: WITHOUT EXTRA PROTECTCARE INDICATION | E51: 64 | F51: 79.953 | G51: 73.7571 | H51: 40.3623 | I51: 3388.3482 | J51: 2840.8843 | K51: 1387.0689 | L51: =SUM(BabycareRaw[[#This Row],[2022]:[YTD 24]]) -> 194.0724
A52: LINDY CAMOMILE W 64 BAG | B52: ITEM | C52: BAGS | D52: WITHOUT EXTRA PROTECTCARE INDICATION | E52: 64 | F52: 12.195 | G52: 8.5598 | H52: 1.6517 | I52: 553.0388 | J52: 369.8305 | K52: 64.1001 | L52: =SUM(BabycareRaw[[#This Row],[2022]:[YTD 24]]) -> 22.4065
A53: LINDY CAMOMILE W 64 BAG KAPAK | B53: ITEM | C53: BAGS | D53: WITHOUT EXTRA PROTECTCARE INDICATION | E53: 64 | F53: 60.5108 | G53: 52.406 | H53: 30.1228 | I53: 2540.1292 | J53: 2011.4869 | K53: 1066.0352 | L53: =SUM(BabycareRaw[[#This Row],[2022]:[YTD 24]]) -> 143.0396
A54: LINDY CREAM W 64 BAG KAPAK | B54: ITEM | C54: BAGS | D54: WITHOUT EXTRA PROTECTCARE INDICATION | E54: 64 | F54: 47.8005 | G54: 51.1991 | H54: 29.6906 | I54: 1970.2178 | J54: 1924.2328 | K54: 1027.8572 | L54: =SUM(BabycareRaw[[#This Row],[2022]:[YTD 24]]) -> 128.6902
A55: LINDY CREAM&VIT.E PH5.5 W 64 BAG | B55: ITEM | C55: BAGS | D55: PH BALANCED | E55: 64 | F55: 0 | G55: 3.2536 | H55: 4.3144 | I55: 0 | J55: 139.3498 | K55: 169.8469 | L55: =SUM(BabycareRaw[[#This Row],[2022]:[YTD 24]]) -> 7.568
A56: LINDY OLIVE OIL EXTR. PH5.5 W 64 BAG | B56: ITEM | C56: BAGS | D56: PH BALANCED | E56: 64 | F56: 5.5922 | G56: 5.3672 | H56: 2.5727 | I56: 261.0479 | J56: 232.436 | K56: 93.9955 | L56: =SUM(BabycareRaw[[#This Row],[2022]:[YTD 24]]) -> 13.5321
A57: LINDY OLIVE OIL EXTR. W 64 BAG KAPAK | B57: ITEM | C57: BAGS | D57: PH BALANCED | E57: 64 | F57: 53.4907 | G57: 44.7837 | H57: 26.4409 | I57: 2262.5698 | J57: 1667.4681 | K57: 920.8814 | L57: =SUM(BabycareRaw[[#This Row],[2022]:[YTD 24]]) -> 124.7153
A58: LINDY SENSITIVE COTTON PH5.5 W 64 BAG | B58: ITEM | C58: BAGS | D58: SENSITIVE | E58: 64 | F58: 8.271 | G58: 9.931 | H58: 1.1805 | I58: 392.0086 | J58: 426.1969 | K58: 46.2808 | L58: =SUM(BabycareRaw[[#This Row],[2022]:[YTD 24]]) -> 19.3825
A59: LINDY SENSITIVE W 64 BAG KAPAK | B59: ITEM | C59: BAGS | D59: SENSITIVE | E59: 64 | F59: 70.5623 | G59: 56.7856 | H59: 30.7966 | I59: 2842.322 | J59: 2121.0371 | K59: 1067.8224 | L59: =SUM(BabycareRaw[[#This Row],[2022]:[YTD 24]]) -> 158.1445
A60: LINDY WHITE TEA&VIT E W 64 BAG | B60: ITEM | C60: BAGS | D60: PH BALANCED | E60: 64 | F60: 34.4959 | G60: 35.3334 | H60: 28.0782 | I60: 1446.3839 | J60: 1359.9783 | K60: 967.9162 | L60: =SUM(BabycareRaw[[#This Row],[2022]:[YTD 24]]) -> 97.9075
...

Sheet data segregation
A1: Items | C1: Manufacturer | E1: Brand | G1: Company | I1: Details | J1: Total Count
A2: BABY2000 CAMOMILLA W 20 BAG ABA SRL | C2: Nova Garbagnate | E2: BABY 2000 | G2: Nova Garbagnate | I2: Manufacturer | J2: =COUNTA(C2:C116) -> 115
A3: BAMBO NATURE W 10 BAG | C3: BeneCare | E3: BAMBO | G3: BeneCare | I3: Brand | J3: =COUNTA(E2:E152) -> 151
A4: BAMBO NATURE W 50 BAG | C4: VigaLife | E4: BABY CREMA | G4: VigaLife | I4: Company | J4: =COUNTA(G2:G108) -> 107
A5: BAMBO NATURE 0%PERFUME W 80 BAG | C5: Intelligent Initiative | E5: LINDY | G5: Intelligent Initiative | I5: Items | J5: =COUNTA(A2:A552) -> 551
A6: BAMBO NATURE W 80 BAG KAPAK | C6: BroadLeaf Group | E6: LUBA | G6: BroadLeaf Group
A7: BABY CREMA PLAY TIME CAMOMILE W 100 PINK | C7: ArborChemistry | E7: HUGGLO | G7: ArborChemistry
A8: BABYCREMA PLAYTIME CAMOMILE W 100 ORANGE | C8: ArkPapers | E8: PAPILION | G8: ArkPapers
A9: BABY CREMA CAMOMIL W 120 BAG KAPAK | C9: Arkana PaperCraft | E9: HONEY BEBISH | G9: Arkana PaperCraft
A10: BABY CREMA ALOE 15 BAG | C10: Fragrantium S.A. | E10: PINE | G10: Fragrantium S.A.
A11: BABY CREMA CAMOMIL W 15 BAG | C11: ArsenicChem | E11: TROMPY | G11: ArsenicChem
A12: BABY CREMA PH5.5 W 3X15/1FR BAG &&& | C12: Creativa Worldwide | E12: HAPPY FRESH | G12: Creativa Worldwide
A13: BABY CREMA WATER 99% W 15 BAG | C13: CultureSana | E13: ULTRA COMPACT | G13: CultureSana
A14: BABY CREMA CAMOMIL W 40 BAG | C14: Ataman Industries | E14: KANZ | G14: Ataman Industries
A15: BABY CREMA COTTON&PANTENOL W 4X56 BAG | C15: AxisOn Group | E15: CHICCO | G15: AxisOn Group
A16: BABY CREMA COTTON&PANTENOL W 56 BAG | C16: PureAim Cleaners | E16: UNI | G16: PureAim Cleaners
A17: BABY CREMA ALOE 64 BAG | C17: AlpineMeadow | E17: EVENT | G17: AlpineMeadow
... A108: AQUELLA TROPIC ALC.FREE W 120 BAG | C108: TAHA KIMYA KOZMETIK | E108: PAMPERS | G108: GreenIlgaz Group
A109: AQUELLA KIDS BABY ALOEVERA&CREAM W 60BAG | C109: TEKSAN | E109: PRIMA | G109: =COUNTA(G2:G108) -> 107
A110: AQUELLA BABY VIT E&PRO B5 W 72 BAG | C110: TNCR GIDA | E110: URIAGE
A111: AQUELLA KIDS BABY PH5.5 W 72 BAG | C111: TRUVA KOZMETIK | E111: BEBECAN
A112: AQUELLA BABY VIT E&PRO B5 W 90 BAG KAPAK | C112: TRUVA KOZMETIK TIC | E112: BIMBO & BIMBA
A113: AURA ULTRA COMF. COTTON HYPOALL. W 100 B | C113: ULTRA COSMETICS | E113: VIBELLE
A114: AURA ULTRA COMFORT COTTON W 63 BAG | C114: UNAC GROUP KOZMETIK SAN. | E114: BELUX
A115: COTTON BABY UL.SOFT CREAM ALC.FREE W 120 | C115: UNILEVER | E115: SECKIN
A116: COTTON BABY PH5.5 AL.FREE W 90 BAG KAPAK | C116: YESIL ILGAZ | E116: SOFT CARE
A117: MIMI NICE BABY PH5.5 W 15 BAG | C117: =COUNTA(C2:C116) -> 115 | E117: HOPS
A118: MY COMFORT BABY ANGEL PH5.5 W 120 BAG | E118: MAXIMENS
A119: MY COMFORT BABY ARGAN ALK.FREE W 120 BAG | E119: DOCTOR
A120: NICEBABY PROVITB5&VITE PH5.5 W 120 BAG | E120: MEDPROFFESIONAL
A121: WINEX BABY PH5.5 W 72 BAG | E121: SPRING LINE
A122: WINEX BABY PROVITB5&VIT.F PH5.5 W 72 BAG | E122: GIAN
A123: FOMEX PH5.5 ALC.FREE W 72 BAG KAPAK | E123: SEBAMED
A124: PADDLERS SOFT&CREAM PROVITB5&VITE W 120 | E124: MAMMI
A125: PADDLERS SOFT&CREAM PROVITB5&VITE W 80 | E125: ASALI
A126: PURE BABY JUMBO PH5.5 W 120 BAG | E126: COTTON SOFT
A127: SLEEPY BABY SENSITIVE 110 W BAG KAPAK | E127: ELVIM
A128: SLEEPY BABY APPLE AL.FREE W 120 BAG | E128: FLAMINGO
A129: SLEEPY BABY LEMON AL.FREE W 120 BAG | E129: INCI
... A152: BERFINY EXTRA BABY W 72 BAG | E152: DOVE
...

Sheet Mgf
B1: Performance Report BY Manufacturer
B2: Growth Metrics | C2: Value ( in $1000) | F2: Volume (in 1000) | I2: Price Impact = | J2: Value growth - Volume growth | M2: Price Validation
C3: YoY Growth | D3: =((D4-C4)/C4) -> 0.032341622 | E3: =((E4-D4)/D4) -> -0.46405413 | F3: Volume YoY | G3: =((G4-F4)/F4) -> -0.0055203387 | H3: =((H4-G4)/G4) -> -0.49415464 | I3: Price Impact | J3: =D3-G3 -> 0.037861961 | K3: =E3-H3 -> 0.030100506 | M3: Price Impact | N3: =((N4-M4)/M4) -> 0.038072132 | O3: =((O4-N4)/N4) -> 0.059505352
B4: Freshclean (official data) | C4: 31416.343 | D4: 32432.398 | E4: 17382.01 | F4: 1194607.9 | G4: 1188013.2 | H4: 600950.98 | I4: Derived Calculation | M4: =C4/F4 -> 0.026298457 | N4: =D4/G4 -> 0.027299695 | O4: =E4/H4 -> 0.028924173
B6: Manufacturer | C6: 2022 | D6: 2023 | E6: YTD 2024 | F6: Volume 2022 | G6: Volume 2023 | H6: Volume 2024 | I6: Total Volume | J6: Total Value | K6: Average Price | L6: YoY Growth | M6: Voume growth | N6: price growth | O6: mini trend line
B7: VigaLife | C7: 3341.5013 | D7: 3428.0437 | E7: 1852.1969 | F7: 125970.25 | G7: 127615.61 | H7: 64977.618 | I7: =SUM(Table4[[#This Row],[Volume 2022]:[Volume 2024]]) -> 318563.48 | J7: 8621.7419 | K7: =Table4[[#This Row],[Total Value]]/Table4[[#This Row],[Total Volume]] -> 0.027064439 | L7: =IFERROR((Table4[[#This Row],[2023]]-Table4[[#This Row],[2022]])/Table4[[#This Row],[2022]],0) -> 0.025899257 | M7: =IFERROR(((Table4[[#This Row],[Volume 2023]]-Table4[[#This Row],[Volume 2022]])/Table4[[#This Row],[Volume 2022]]),0) -> 0.013061496 | N7: =IFERROR(Table4[[#This Row],[YoY Growth]]-Table4[[#This Row],[Voume growth]],0) -> 0.01283776
B8: Proctor & Wager | C8: 1818.5395 | D8: 2101.705 | E8: 1233.5607 | F8: 45983.128 | G8: 53803.279 | H8: 29897.358 | I8: =SUM(Table4[[#This Row],[Volume 2022]:[Volume 2024]]) -> 129683.76 | J8: 5153.8052 | K8: =Table4[[#This Row],[Total Value]]/Table4[[#This Row],[Total Volume]] -> 0.03974133 | L8: =IFERROR((Table4[[#This Row],[2023]]-Table4[[#This Row],[2022]])/Table4[[#This Row],[2022]],0) -> 0.15571039 | M8: =IFERROR(((Table4[[#This Row],[Volume 2023]]-Table4[[#This Row],[Volume 2022]])/Table4[[#This Row],[Volume 2022]]),0) -> 0.17006566 | N8: =IFERROR(Table4[[#This Row],[YoY Growth]]-Table4[[#This Row],[Voume growth]],0) -> -0.014355269
B9: Fulya Beauty | C9: 1012.9229 | D9: 822.981 | E9: 367.9876 | F9: 57405.586 | G9: 44546.773 | H9: 18766.233 | I9: =SUM(Table4[[#This Row],[Volume 2022]:[Volume 2024]]) -> 120718.59 | J9: 2203.8915 | K9: =Table4[[#This Row],[Total Value]]/Table4[[#This Row],[Total Volume]] -> 0.018256438 | L9: =IFERROR((Table4[[#This Row],[2023]]-Table4[[#This Row],[2022]])/Table4[[#This Row],[2022]],0) -> -0.18751862 | M9: =IFERROR(((Table4[[#This Row],[Volume 2023]]-Table4[[#This Row],[Volume 2022]])/Table4[[#This Row],[Volume 2022]]),0) -> -0.22399933 | N9: =IFERROR(Table4[[#This Row],[YoY Growth]]-Table4[[#This Row],[Voume growth]],0) -> 0.036480711
B10: SepaTextiles | C10: 632.9619 | D10: 529.4104 | E10: 262.1375 | F10: 36136.764 | G10: 28913.012 | H10: 13646.294 | I10: =SUM(Table4[[#This Row],[Volume 2022]:[Volume 2024]]) -> 78696.07 | J10: 1424.5098 | K10: =Table4[[#This Row],[Total Value]]/Table4[[#This Row],[Total Volume]] -> 0.01810141 | L10: =IFERROR((Table4[[#This Row],[2023]]-Table4[[#This Row],[2022]])/Table4[[#This Row],[2022]],0) -> -0.16359831 | M10: =IFERROR(((Table4[[#This Row],[Volume 2023]]-Table4[[#This Row],[Volume 2022]])/Table4[[#This Row],[Volume 2022]]),0) -> -0.19990037 | N10: =IFERROR(Table4[[#This Row],[YoY Growth]]-Table4[[#This Row],[Voume growth]],0) -> 0.036302056
B11: Intelligent Initiative | C11: 511.7809 | D11: 507.3048 | E11: 295.7138 | F11: 23199.702 | G11: 21680.539 | H11: 11434.484 | I11: =SUM(Table4[[#This Row],[Volume 2022]:[Volume 2024]]) -> 56314.725 | J11: 1314.7995 | K11: =Table4[[#This Row],[Total Value]]/Table4[[#This Row],[Total Volume]] -> 0.023347348 | L11: =IFERROR((Table4[[#This Row],[2023]]-Table4[[#This Row],[2022]])/Table4[[#This Row],[2022]],0) -> -0.0087461255 | M11: =IFERROR(((Table4[[#This Row],[Volume 2023]]-Table4[[#This Row],[Volume 2022]])/Table4[[#This Row],[Volume 2022]]),0) -> -0.065481993 | N11: =IFERROR(Table4[[#This Row],[YoY Growth]]-Table4[[#This Row],[Voume growth]],0) -> 0.056735867
B12: AxisOn Group | C12: 471.6447 | D12: 448.0015 | E12: 276.1403 | F12: 13724.156 | G12: 13181.351 | H12: 8823.5241 | I12: =SUM(Table4[[#This Row],[Volume 2022]:[Volume 2024]]) -> 35729.032 | J12: 1195.7865 | K12: =Table4[[#This Row],[Total Value]]/Table4[[#This Row],[Total Volume]] -> 0.033468203 | L12: =IFERROR((Table4[[#This Row],[2023]]-Table4[[#This Row],[2022]])/Table4[[#This Row],[2022]],0) -> -0.05012926 | M12: =IFERROR(((Table4[[#This Row],[Volume 2023]]-Table4[[#This Row],[Volume 2022]])/Table4[[#This Row],[Volume 2022]]),0) -> -0.039551086 | N12: =IFERROR(Table4[[#This Row],[YoY Growth]]-Table4[[#This Row],[Voume growth]],0) -> -0.010578174
B13: Lara Beauty | C13: 394.6838 | D13: 409.4961 | E13: 321.2638 | F13: 18974.914 | G13: 19732.122 | H13: 15809.169 | I13: =SUM(Table4[[#This Row],[Volume 2022]:[Volume 2024]]) -> 54516.205 | J13: 1125.4437 | K13: =Table4[[#This Row],[Total Value]]/Table4[[#This Row],[Total Volume]] -> 0.020644205 | L13: =IFERROR((Table4[[#This Row],[2023]]-Table4[[#This Row],[2022]])/Table4[[#This Row],[2022]],0) -> 0.037529536 | M13: =IFERROR(((Table4[[#This Row],[Volume 2023]]-Table4[[#This Row],[Volume 2022]])/Table4[[#This Row],[Volume 2022]]),0) -> 0.039905757 | N13: =IFERROR(Table4[[#This Row],[YoY Growth]]-Table4[[#This Row],[Voume growth]],0) -> -0.0023762207
B14: LifeChem | C14: 332.0165 | D14: 406.0936 | E14: 185.505 | F14: 9811.9591 | G14: 12002.149 | H14: 5143.8028 | I14: =SUM(Table4[[#This Row],[Volume 2022]:[Volume 2024]]) -> 26957.911 | J14: 923.6151 | K14: =Table4[[#This Row],[Total Value]]/Table4[[#This Row],[Total Volume]] -> 0.034261375 | L14: =IFERROR((Table4[[#This Row],[2023]]-Table4[[#This Row],[2022]])/Table4[[#This Row],[2022]],0) -> 0.22311271 | M14: =IFERROR(((Table4[[#This Row],[Volume 2023]]-Table4[[#This Row],[Volume 2022]])/Table4[[#This Row],[Volume 2022]]),0) -> 0.22321638 | N14: =IFERROR(Table4[[#This Row],[YoY Growth]]-Table4[[#This Row],[Voume growth]],0) -> -0.00010367417
B15: LovelyCo | C15: 466.315 | D15: 321.9937 | E15: 119.931 | F15: 27928.057 | G15: 19049.503 | H15: 6464.4501 | I15: =SUM(Table4[[#This Row],[Volume 2022]:[Volume 2024]]) -> 53442.009 | J15: 908.2397 | K15: =Table4[[#This Row],[Total Value]]/Table4[[#This Row],[Total Volume]] -> 0.016994864 | L15: =IFERROR((Table4[[#This Row],[2023]]-Table4[[#This Row],[2022]])/Table4[[#This Row],[2022]],0) -> -0.30949315 | M15: =IFERROR(((Table4[[#This Row],[Volume 2023]]-Table4[[#This Row],[Volume 2022]])/Table4[[#This Row],[Volume 2022]]),0) -> -0.31790805 | N15: =IFERROR(Table4[[#This Row],[YoY Growth]]-Table4[[#This Row],[Voume growth]],0) -> 0.0084148957
B16: Giga S.A. | C16: 336.5155 | D16: 318.6227 | E16: 125.7655 | F16: 10227.006 | G16: 9928.9132 | H16: 3640.5189 | I16: =SUM(Table4[[#This Row],[Volume 2022]:[Volume 2024]]) -> 23796.438 | J16: 780.9037 | K16: =Table4[[#This Row],[Total Value]]/Table4[[#This Row],[Total Volume]] -> 0.032815991 | L16: =IFERROR((Table4[[#This Row],[2023]]-Table4[[#This Row],[2022]])/Table4[[#This Row],[2022]],0) -> -0.053170805 | M16: =IFERROR(((Table4[[#This Row],[Volume 2023]]-Table4[[#This Row],[Volume 2022]])/Table4[[#This Row],[Volume 2022]]),0) -> -0.029147583 | N16: =IFERROR(Table4[[#This Row],[YoY Growth]]-Table4[[#This Row],[Voume growth]],0) -> -0.024023222
B17: CleanHarper | C17: 230.7484 | D17: 302.066 | E17: 144.0025 | F17: 11792.665 | G17: 15544.817 | H17: 7126.6583 | I17: =SUM(Table4[[#This Row],[Volume 2022]:[Volume 2024]]) -> 34464.141 | J17: 676.8169 | K17: =Table4[[#This Row],[Total Value]]/Table4[[#This Row],[Total Volume]] -> 0.019638293 | L17: =IFERROR((Table4[[#This Row],[2023]]-Table4[[#This Row],[2022]])/Table4[[#This Row],[2022]],0) -> 0.30907083 | M17: =IFERROR(((Table4[[#This Row],[Volume 2023]]-Table4[[#This Row],[Volume 2022]])/Table4[[#This Row],[Volume 2022]]),0) -> 0.31817677 | N17: =IFERROR(Table4[[#This Row],[YoY Growth]]-Table4[[#This Row],[Voume growth]],0) -> -0.0091059332
B18: CelticWind Ltd | C18: 220.2779 | D18: 271.9985 | E18: 141.2388 | F18: 1748.9224 | G18: 2358.5315 | H18: 1240.7412 | I18: =SUM(Table4[[#This Row],[Volume 2022]:[Volume 2024]]) -> 5348.1951 | J18: 633.5152 | K18: =Table4[[#This Row],[Total Value]]/Table4[[#This Row],[Total Volume]] -> 0.11845402 | L18: =IFERROR((Table4[[#This Row],[2023]]-Table4[[#This Row],[2022]])/Table4[[#This Row],[2022]],0) -> 0.23479705 | M18: =IFERROR(((Table4[[#This Row],[Volume 2023]]-Table4[[#This Row],[Volume 2022]])/Table4[[#This Row],[Volume 2022]]),0) -> 0.34856269 | N18: =IFERROR(Table4[[#This Row],[YoY Growth]]-Table4[[#This Row],[Voume growth]],0) -> -0.11376565
... B26: ArkPapers | C26: 104.6663 | D26: 94.4256 | E26: 45.9485 | F26: 5728.6422 | G26: 5002.3734 | H26: 2228.919 | I26: =SUM(Table4[[#This Row],[Volume 2022]:[Volume 2024]]) -> 12959.935 | J26: 245.0404 | K26: =Table4[[#This Row],[Total Value]]/Table4[[#This Row],[Total Volume]] -> 0.018907534 | L26: =IFERROR((Table4[[#This Row],[2023]]-Table4[[#This Row],[2022]])/Table4[[#This Row],[2022]],0) -> -0.097841426 | M26: =IFERROR(((Table4[[#This Row],[Volume 2023]]-Table4[[#This Row],[Volume 2022]])/Table4[[#This Row],[Volume 2022]]),0) -> -0.12677852 | N26: =IFERROR(Table4[[#This Row],[YoY Growth]]-Table4[[#This Row],[Voume growth]],0) -> 0.028937098
B27: AlpineMeadow | C27: 113.3088 | D27: 81.3137 | E27: 48.2974 | F27: 1483.433 | G27: 1045.7734 | H27: 598.3963 | I27: =SUM(Table4[[#This Row],[Volume 2022]:[Volume 2024]]) -> 3127.6027 | J27: 242.9199 | K27: =Table4[[#This Row],[Total Value]]/Table4[[#This Row],[Total Volume]] -> 0.07766968 | L27: =IFERROR((Table4[[#This Row],[2023]]-Table4[[#This Row],[2022]])/Table4[[#This Row],[2022]],0) -> -0.28237083 | M27: =IFERROR(((Table4[[#This Row],[Volume 2023]]-Table4[[#This Row],[Volume 2022]])/Table4[[#This Row],[Volume 2022]]),0) -> -0.29503159
B28: QueenTrade LTD | C28: 78.6128 | D28: 83.7331 | E28: 33.0609 | F28: 5148.8363 | G28: 5284.2041 | H28: 2040.6587 | I28: =SUM(Table4[[#This Row],[Volume 2022]:[Volume 2024]]) -> 12473.699 | J28: 195.4068 | K28: =Table4[[#This Row],[Total Value]]/Table4[[#This Row],[Total Volume]] -> 0.015665505 | L28: =IFERROR((Table4[[#This Row],[2023]]-Table4[[#This Row],[2022]])/Table4[[#This Row],[2022]],0) -> 0.065133159 | M28: =IFERROR(((Table4[[#This Row],[Volume 2023]]-Table4[[#This Row],[Volume 2022]])/Table4[[#This Row],[Volume 2022]]),0) -> 0.02629095
B29: MoreBeauty | C29: 27.2049 | D29: 84.9624 | E29: 67.9348 | F29: 1705.1168 | G29: 4625.1881 | H29: 3467.3735 | I29: =SUM(Table4[[#This Row],[Volume 2022]:[Volume 2024]]) -> 9797.6784 | J29: 180.1021 | K29: =Table4[[#This Row],[Total Value]]/Table4[[#This Row],[Total Volume]] -> 0.01838212 | L29: =IFERROR((Table4[[#This Row],[2023]]-Table4[[#This Row],[2022]])/Table4[[#This Row],[2022]],0) -> 2.123055 | M29: =IFERROR(((Table4[[#This Row],[Volume 2023]]-Table4[[#This Row],[Volume 2022]])/Table4[[#This Row],[Volume 2022]]),0) -> 1.7125345
B30: ClearSight | C30: 36.0259 | D30: 55.2294 | E30: 85.1398 | F30: 1024.5518 | G30: 1623.7086 | H30: 2439.0855 | I30: =SUM(Table4[[#This Row],[Volume 2022]:[Volume 2024]]) -> 5087.3459 | J30: 176.3951 | K30: =Table4[[#This Row],[Total Value]]/Table4[[#This Row],[Total Volume]] -> 0.034673306 | L30: =IFERROR((Table4[[#This Row],[2023]]-Table4[[#This Row],[2022]])/Table4[[#This Row],[2022]],0) -> 0.53304706 | M30: =IFERROR(((Table4[[#This Row],[Volume 2023]]-Table4[[#This Row],[Volume 2022]])/Table4[[#This Row],[Volume 2022]]),0) -> 0.58479893
B31: Swift GMBH | C31: 113.4864 | D31: 49.0462 | E31: 12.333 | F31: 2663.5762 | G31: 1050.6376 | H31: 244.3868 | I31: =SUM(Table4[[#This Row],[Volume 2022]:[Volume 2024]]) -> 3958.6006 | J31: 174.8656 | K31: =Table4[[#This Row],[Total Value]]/Table4[[#This Row],[Total Volume]] -> 0.04417359 | L31: =IFERROR((Table4[[#This Row],[2023]]-Table4[[#This Row],[2022]])/Table4[[#This Row],[2022]],0) -> -0.5678231 | M31: =IFERROR(((Table4[[#This Row],[Volume 2023]]-Table4[[#This Row],[Volume 2022]])/Table4[[#This Row],[Volume 2022]]),0) -> -0.60555377
B32: SigmaKappaZeta Co. | C32: 26.3474 | D32: 72.5916 | E32: 62.0075 | F32: 920.468 | G32: 3084.2016 | H32: 2719.9431 | I32: =SUM(Table4[[#This Row],[Volume 2022]:[Volume 2024]]) -> 6724.6127 | J32: 160.9465 | K32: =Table4[[#This Row],[Total Value]]/Table4[[#This Row],[Total Volume]] -> 0.023933943 | L32: =IFERROR((Table4[[#This Row],[2023]]-Table4[[#This Row],[2022]])/Table4[[#This Row],[2022]],0) -> 1.7551713 | M32: =IFERROR(((Table4[[#This Row],[Volume 2023]]-Table4[[#This Row],[Volume 2022]])/Table4[[#This Row],[Volume 2022]]),0) -> 2.3506886
B33: Moratex Group / Tobi MegaGroup LTD | C33: 62.7235 | D33: 72.771 | E33: 17.986 | F33: 4142.5168 | G33: 3738.1193 | H33: 966.622 | I33: =SUM(Table4[[#This Row],[Volume 2022]:[Volume 2024]]) -> 8847.2581 | J33: 153.4805 | K33: =Table4[[#This Row],[Total Value]]/Table4[[#This Row],[Total Volume]] -> 0.017347804 | L33: =IFERROR((Table4[[#This Row],[2023]]-Table4[[#This Row],[2022]])/Table4[[#This Row],[2022]],0) -> 0.16018717 | M33: =IFERROR(((Table4[[#This Row],[Volume 2023]]-Table4[[#This Row],[Volume 2022]])/Table4[[#This Row],[Volume 2022]]),0) -> -0.097621209
B34: RoseBeauty | C34: 77.6523 | D34: 36.3665 | E34: 17.4222 | F34: 3136.2818 | G34: 1512.1391 | H34: 684.8154 | I34: =SUM(Table4[[#This Row],[Volume 2022]:[Volume 2024]]) -> 5333.2363 | J34: 131.441 | K34: =Table4[[#This Row],[Total Value]]/Table4[[#This Row],[Total Volume]] -> 0.024645636 | L34: =IFERROR((Table4[[#This Row],[2023]]-Table4[[#This Row],[2022]])/Table4[[#This Row],[2022]],0) -> -0.53167517 | M34: =IFERROR(((Table4[[#This Row],[Volume 2023]]-Table4[[#This Row],[Volume 2022]])/Table4[[#This Row],[Volume 2022]]),0) -> -0.51785611
B35: ColorSan | C35: 65.8637 | D35: 45.3406 | E35: 13.16 | F35: 4126.7388 | G35: 2357.3104 | H35: 741.5008 | I35: =SUM(Table4[[#This Row],[Volume 2022]:[Volume 2024]]) -> 7225.55 | J35: 124.3643 | K35: =Table4[[#This Row],[Total Value]]/Table4[[#This Row],[Total Volume]] -> 0.017211742 | L35: =IFERROR((Table4[[#This Row],[2023]]-Table4[[#This Row],[2022]])/Table4[[#This Row],[2022]],0) -> -0.31159956 | M35: =IFERROR(((Table4[[#This Row],[Volume 2023]]-Table4[[#This Row],[Volume 2022]])/Table4[[#This Row],[Volume 2022]]),0) -> -0.4287716
B36: BladeSon LTD | C36: 55.0965 | D36: 43.3481 | E36: 24.53 | F36: 2000.4357 | G36: 1647.0114 | H36: 929.3516 | I36: =SUM(Table4[[#This Row],[Volume 2022]:[Volume 2024]]) -> 4576.7987 | J36: 122.9746 | K36: =Table4[[#This Row],[Total Value]]/Table4[[#This Row],[Total Volume]] -> 0.02686913 | L36: =IFERROR((Table4[[#This Row],[2023]]-Table4[[#This Row],[2022]])/Table4[[#This Row],[2022]],0) -> -0.21323315 | M36: =IFERROR(((Table4[[#This Row],[Volume 2023]]-Table4[[#This Row],[Volume 2022]])/Table4[[#This Row],[Volume 2022]]),0) -> -0.17667366
B37: EuroPack Communications SRL | C37: 60.8995 | D37: 35.9794 | E37: 13.2829 | F37: 1646.9927 | G37: 1006.4904 | H37: 408.4543 | I37: =SUM(Table4[[#This Row],[Volume 2022]:[Volume 2024]]) -> 3061.9374 | J37: 110.1618 | K37: =Table4[[#This Row],[Total Value]]/Table4[[#This Row],[Total Volume]] -> 0.035977809 | L37: =IFERROR((Table4[[#This Row],[2023]]-Table4[[#This Row],[2022]])/Table4[[#This Row],[2022]],0) -> -0.4092004 | M37: =IFERROR(((Table4[[#This Row],[Volume 2023]]-Table4[[#This Row],[Volume 2022]])/Table4[[#This Row],[Volume 2022]]),0) -> -0.38889201
B38: UniHandle | C38: 19.4955 | D38: 39.7614 | E38: 26.2695 | F38: 286.0496 | G38: 652.1086 | H38: 499.8379 | I38: =SUM(Table4[[#This Row],[Volume 2022]:[Volume 2024]]) -> 1437.9961 | J38: 85.5264 | K38: =Table4[[#This Row],[Total Value]]/Table4[[#This Row],[Total Volume]] -> 0.0594761 | L38: =IFERROR((Table4[[#This Row],[2023]]-Table4[[#This Row],[2022]])/Table4[[#This Row],[2022]],0) -> 1.0395168 | M38: =IFERROR(((Table4[[#This Row],[Volume 2023]]-Table4[[#This Row],[Volume 2022]])/Table4[[#This Row],[Volume 2022]]),0) -> 1.2797046
... B113: MegaBeauty | C113: 0 | D113: 0 | E113: 0 | F113: 0 | G113: 0 | H113: 0 | I113: =SUM(Table4[[#This Row],[Volume 2022]:[Volume 2024]]) -> 0 | J113: 0 | K113: =Table4[[#This Row],[Total Value]]/Table4[[#This Row],[Total Volume]] -> #DIV/0! | L113: =IFERROR((Table4[[#This Row],[2023]]-Table4[[#This Row],[2022]])/Table4[[#This Row],[2022]],0) -> 0 | M113: =IFERROR(((Table4[[#This Row],[Volume 2023]]-Table4[[#This Row],[Volume 2022]])/Table4[[#This Row],[Volume 2022]]),0) -> 0

Sheet pivot by mfg.
A1: Sales Performance report (Manufacturer)
A2: By Value
A3: Row Labels | B3: Sum of Value 2022 | C3: Sum of Value 2023 | D3: Sum of Value YTD 2024 | E3: Sum of Total Value
A4: VigaLife | B4: 3341.5013 | C4: 3428.0437 | D4: 1852.1969 | E4: 8621.7419
A5: Proctor & Wager | B5: 1818.5395 | C5: 2101.705 | D5: 1233.5607 | E5: 5153.8052
A6: Fulya Beauty | B6: 1012.9229 | C6: 822.981 | D6: 367.9876 | E6: 2203.8915
A7: SepaTextiles | B7: 632.9619 | C7: 529.4104 | D7: 262.1375 | E7: 1424.5098
A8: Intelligent Initiative | B8: 511.7809 | C8: 507.3048 | D8: 295.7138 | E8: 1314.7995
A9: Grand Total | B9: 7317.7065 | C9: 7389.4449 | D9: 4011.5965 | E9: 18718.748
A14: BY volume
A15: Row Labels | B15: Sum of Volume 2022 | C15: Sum of Volume 2023 | D15: Sum of Volume 2024 | E15: Sum of Average Volume | F15: Sum of Total Value
A16: VigaLife | B16: 125970.25 | C16: 127615.61 | D16: 64977.618 | E16: 106187.83 | F16: 8621.7419
A17: Proctor & Wager | B17: 45983.128 | C17: 53803.279 | D17: 29897.358 | E17: 43227.921 | F17: 5153.8052
A18: Fulya Beauty | B18: 57405.586 | C18: 44546.773 | D18: 18766.233 | E18: 40239.531 | F18: 2203.8915
A19: SepaTextiles | B19: 36136.764 | C19: 28913.012 | D19: 13646.294 | E19: 26232.023 | F19: 1424.5098
A20: Intelligent Initiative | B20: 23199.702 | C20: 21680.539 | D20: 11434.484 | E20: 18771.575 | F20: 1314.7995
A21: Grand Total | B21: 288695.43 | C21: 276559.21 | D21: 138721.99 | E21: 234658.88 | F21: 18718.748

Sheet Brand
B1: Performance report by Brand
B2: Growth Metrics | C2: Value ( in $1000) | F2: Volume (in 1000) | I2: Price Impact = | J2: Value growth - Volume growth | M2: Price Validation
C3: YoY Growth | D3: =((D4-C4)/C4) -> 0.032341622 | E3: =((E4-D4)/D4) -> -0.46405413 | F3: Volume YoY | G3: =((G4-F4)/F4) -> -0.0055203387 | H3: =((H4-G4)/G4) -> -0.49415464 | I3: Price Impact | J3: =D3-G3 -> 0.037861961 | K3: =E3-H3 -> 0.030100506 | M3: Price Impact | N3: =((N4-M4)/M4) -> 0.038072132 | O3: =((O4-N4)/N4) -> 0.059505352
B4: Freshclean (official data) | C4: 31416.343 | D4: 32432.398 | E4: 17382.01 | F4: 1194607.9 | G4: 1188013.2 | H4: 600950.98 | I4: Derived Calculation | M4: =C4/F4 -> 0.026298457 | N4: =D4/G4 -> 0.027299695 | O4: =E4/H4 -> 0.028924173
B6: in 000s | C6: 2022 | D6: 2023 | E6: YTD 2024 | F6: Volume 2022 | G6: Volume 2023 | H6: Volume YTD 2024 | I6: Total Volume | J6: Total Value | K6: YoY growth | L6: Volume growth | M6: price growth | N6: mini trend line
B7: BABY CREMA (VigaLife) | C7: 3341.5013 | D7: 3428.0437 | E7: 1852.1969 | F7: 125970.25 | G7: 127615.61 | H7: 64977.618 | I7: =SUM(Table7[[#This Row],[Volume 2022]:[Volume YTD 2024]]) -> 318563.48 | J7: 8621.7419 | K7: =IFERROR(((Table7[[#This Row],[2023]]-Table7[[#This Row],[2022]])/Table7[[#This Row],[2022]]),0) -> 0.025899257 | L7: =IFERROR(((Table7[[#This Row],[Volume 2023]]-Table7[[#This Row],[Volume 2022]])/Table7[[#This Row],[Volume 2022]]),0) -> 0.013061496 | M7: =Table7[[#This Row],[YoY growth]]-Table7[[#This Row],[Volume growth]] -> 0.01283776
B8: PAMPERS (PROCTER & GAMBLE) | C8: 1818.1666 | D8: 2101.6939 | E8: 1233.5607 | F8: 45975.839 | G8: 53803.039 | H8: 29897.358 | I8: =SUM(Table7[[#This Row],[Volume 2022]:[Volume YTD 2024]]) -> 129676.24 | J8: 5153.4212 | K8: =IFERROR(((Table7[[#This Row],[2023]]-Table7[[#This Row],[2022]])/Table7[[#This Row],[2022]]),0) -> 0.15594132 | L8: =IFERROR(((Table7[[#This Row],[Volume 2023]]-Table7[[#This Row],[Volume 2022]])/Table7[[#This Row],[Volume 2022]]),0) -> 0.17024595 | M8: =Table7[[#This Row],[YoY growth]]-Table7[[#This Row],[Volume growth]] -> -0.014304632
B9: LINDY (Intelligent Initiative) | C9: 511.7809 | D9: 507.3048 | E9: 295.7138 | F9: 23199.702 | G9: 21680.539 | H9: 11434.484 | I9: =SUM(Table7[[#This Row],[Volume 2022]:[Volume YTD 2024]]) -> 56314.725 | J9: 1314.7995 | K9: =IFERROR(((Table7[[#This Row],[2023]]-Table7[[#This Row],[2022]])/Table7[[#This Row],[2022]]),0) -> -0.0087461255 | L9: =IFERROR(((Table7[[#This Row],[Volume 2023]]-Table7[[#This Row],[Volume 2022]])/Table7[[#This Row],[Volume 2022]]),0) -> -0.065481993 | M9: =Table7[[#This Row],[YoY growth]]-Table7[[#This Row],[Volume growth]] -> 0.056735867
B10: EVENT (AxisOn Group) | C10: 471.6447 | D10: 448.0015 | E10: 276.1403 | F10: 13724.156 | G10: 13181.351 | H10: 8823.5241 | I10: =SUM(Table7[[#This Row],[Volume 2022]:[Volume YTD 2024]]) -> 35729.032 | J10: 1195.7865 | K10: =IFERROR(((Table7[[#This Row],[2023]]-Table7[[#This Row],[2022]])/Table7[[#This Row],[2022]]),0) -> -0.05012926 | L10: =IFERROR(((Table7[[#This Row],[Volume 2023]]-Table7[[#This Row],[Volume 2022]])/Table7[[#This Row],[Volume 2022]]),0) -> -0.039551086 | M10: =Table7[[#This Row],[YoY growth]]-Table7[[#This Row],[Volume growth]] -> -0.010578174
B11: LARA (LARA KOZMETIK) | C11: 394.4622 | D11: 406.9338 | E11: 320.2154 | F11: 18966.536 | G11: 19594.109 | H11: 15751.087 | I11: =SUM(Table7[[#This Row],[Volume 2022]:[Volume YTD 2024]]) -> 54311.731 | J11: 1121.6114 | K11: =IFERROR(((Table7[[#This Row],[2023]]-Table7[[#This Row],[2022]])/Table7[[#This Row],[2022]]),0) -> 0.031616718 | L11: =IFERROR(((Table7[[#This Row],[Volume 2023]]-Table7[[#This Row],[Volume 2022]])/Table7[[#This Row],[Volume 2022]]),0) -> 0.033088457 | M11: =Table7[[#This Row],[YoY growth]]-Table7[[#This Row],[Volume growth]] -> -0.0014717397
B12: FRESHMAKER (FULYA COSMETICS) | C12: 447.5816 | D12: 351.9512 | E12: 140.7477 | F12: 23420.14 | G12: 17186.266 | H12: 6668.4121 | I12: =SUM(Table7[[#This Row],[Volume 2022]:[Volume YTD 2024]]) -> 47274.819 | J12: 940.2805 | K12: =IFERROR(((Table7[[#This Row],[2023]]-Table7[[#This Row],[2022]])/Table7[[#This Row],[2022]]),0) -> -0.21366026 | L12: =IFERROR(((Table7[[#This Row],[Volume 2023]]-Table7[[#This Row],[Volume 2022]])/Table7[[#This Row],[Volume 2022]]),0) -> -0.26617577 | M12: =Table7[[#This Row],[YoY growth]]-Table7[[#This Row],[Volume growth]] -> 0.052515513
B13: MOLFIX (HAYAT KIMYA) | C13: 332.0165 | D13: 406.0936 | E13: 185.505 | F13: 9811.9591 | G13: 12002.149 | H13: 5143.8028 | I13: =SUM(Table7[[#This Row],[Volume 2022]:[Volume YTD 2024]]) -> 26957.911 | J13: 923.6151 | K13: =IFERROR(((Table7[[#This Row],[2023]]-Table7[[#This Row],[2022]])/Table7[[#This Row],[2022]]),0) -> 0.22311271 | L13: =IFERROR(((Table7[[#This Row],[Volume 2023]]-Table7[[#This Row],[Volume 2022]])/Table7[[#This Row],[Volume 2022]]),0) -> 0.22321638 | M13: =Table7[[#This Row],[YoY growth]]-Table7[[#This Row],[Volume growth]] -> -0.00010367417
B14: COTTON SOFT (SEPA MENSUCAT) | C14: 306.9256 | D14: 309.6565 | E14: 149.7295 | F14: 16220.671 | G14: 15817.587 | H14: 7239.5673 | I14: =SUM(Table7[[#This Row],[Volume 2022]:[Volume YTD 2024]]) -> 39277.825 | J14: 766.3116 | K14: =IFERROR(((Table7[[#This Row],[2023]]-Table7[[#This Row],[2022]])/Table7[[#This Row],[2022]]),0) -> 0.008897596 | L14: =IFERROR(((Table7[[#This Row],[Volume 2023]]-Table7[[#This Row],[Volume 2022]])/Table7[[#This Row],[Volume 2022]]),0) -> -0.024850063 | M14: =Table7[[#This Row],[YoY growth]]-Table7[[#This Row],[Volume growth]] -> 0.033747659
B15: RENKLI (SEVIMLER) | C15: 396.2448 | D15: 253.7248 | E15: 99.1285 | F15: 23444.317 | G15: 14396.69 | H15: 5148.9142 | I15: =SUM(Table7[[#This Row],[Volume 2022]:[Volume YTD 2024]]) -> 42989.921 | J15: 749.0981 | K15: =IFERROR(((Table7[[#This Row],[2023]]-Table7[[#This Row],[2022]])/Table7[[#This Row],[2022]]),0) -> -0.35967664 | L15: =IFERROR(((Table7[[#This Row],[Volume 2023]]-Table7[[#This Row],[Volume 2022]])/Table7[[#This Row],[Volume 2022]]),0) -> -0.38591981 | M15: =Table7[[#This Row],[YoY growth]]-Table7[[#This Row],[Volume growth]] -> 0.02624317
B16: BABY CARE (MEGA) | C16: 277.9267 | D16: 310.4148 | E16: 125.3454 | F16: 8929.9618 | G16: 9775.1643 | H16: 3632.8902 | I16: =SUM(Table7[[#This Row],[Volume 2022]:[Volume YTD 2024]]) -> 22338.016 | J16: 713.6869 | K16: =IFERROR(((Table7[[#This Row],[2023]]-Table7[[#This Row],[2022]])/Table7[[#This Row],[2022]]),0) -> 0.11689449 | L16: =IFERROR(((Table7[[#This Row],[Volume 2023]]-Table7[[#This Row],[Volume 2022]])/Table7[[#This Row],[Volume 2022]]),0) -> 0.094647941 | M16: =Table7[[#This Row],[YoY growth]]-Table7[[#This Row],[Volume growth]] -> 0.022246549
B17: PETINO (HARPER HYGIENICS) | C17: 230.7484 | D17: 299.0139 | E17: 143.2444 | F17: 11792.665 | G17: 15508.35 | H17: 7115.8299 | I17: =SUM(Table7[[#This Row],[Volume 2022]:[Volume YTD 2024]]) -> 34416.845 | J17: 673.0067 | K17: =IFERROR(((Table7[[#This Row],[2023]]-Table7[[#This Row],[2022]])/Table7[[#This Row],[2022]]),0) -> 0.29584387 | L17: =IFERROR(((Table7[[#This Row],[Volume 2023]]-Table7[[#This Row],[Volume 2022]])/Table7[[#This Row],[Volume 2022]]),0) -> 0.31508435 | M17: =Table7[[#This Row],[YoY growth]]-Table7[[#This Row],[Volume growth]] -> -0.01924048
B18: WATER WIPES (IRISH BREEZE LTD) | C18: 220.2779 | D18: 271.9985 | E18: 141.2388 | F18: 1748.9224 | G18: 2358.5315 | H18: 1240.7412 | I18: =SUM(Table7[[#This Row],[Volume 2022]:[Volume YTD 2024]]) -> 5348.1951 | J18: 633.5152 | K18: =IFERROR(((Table7[[#This Row],[2023]]-Table7[[#This Row],[2022]])/Table7[[#This Row],[2022]]),0) -> 0.23479705 | L18: =IFERROR(((Table7[[#This Row],[Volume 2023]]-Table7[[#This Row],[Volume 2022]])/Table7[[#This Row],[Volume 2022]]),0) -> 0.34856269 | M18: =Table7[[#This Row],[YoY growth]]-Table7[[#This Row],[Volume growth]] -> -0.11376565
... B26: PURE (FULYA COSMETICS) | C26: 137.1788 | D26: 116.5658 | E26: 65.9129 | F26: 7929.3796 | G26: 6740.5911 | H26: 3524.3125 | I26: =SUM(Table7[[#This Row],[Volume 2022]:[Volume YTD 2024]]) -> 18194.283 | J26: 319.6575 | K26: =IFERROR(((Table7[[#This Row],[2023]]-Table7[[#This Row],[2022]])/Table7[[#This Row],[2022]]),0) -> -0.15026374 | L26: =IFERROR(((Table7[[#This Row],[Volume 2023]]-Table7[[#This Row],[Volume 2022]])/Table7[[#This Row],[Volume 2022]]),0) -> -0.14992201 | M26: =Table7[[#This Row],[YoY growth]]-Table7[[#This Row],[Volume growth]] -> -0.00034173687
B27: ELAN (Esburg Health) | C27: 0 | D27: 170.6652 | E27: 101.533 | F27: 0 | G27: 10947.356 | H27: 5713.8589 | I27: =SUM(Table7[[#This Row],[Volume 2022]:[Volume YTD 2024]]) -> 16661.215 | J27: 272.1982 | K27: =IFERROR(((Table7[[#This Row],[2023]]-Table7[[#This Row],[2022]])/Table7[[#This Row],[2022]]),0) -> 0 | L27: =IFERROR(((Table7[[#This Row],[YTD 2024]]-Table7[[#This Row],[2023]])/Table7[[#This Row],[2023]]),0) -> -0.40507497 | M27: =Table7[[#This Row],[YoY growth]]-Table7[[#This Row],[Volume growth]] -> 0.40507497
B28: SLEEPY ( ErusHealth Products) | C28: 27.8421 | D28: 189.2274 | E28: 44.1349 | F28: 1267.7428 | G28: 11056.59 | H28: 2900.9743 | I28: =SUM(Table7[[#This Row],[Volume 2022]:[Volume YTD 2024]]) -> 15225.307 | J28: 261.2044 | K28: =IFERROR(((Table7[[#This Row],[2023]]-Table7[[#This Row],[2022]])/Table7[[#This Row],[2022]]),0) -> 5.7964485 | L28: =IFERROR(((Table7[[#This Row],[YTD 2024]]-Table7[[#This Row],[2023]])/Table7[[#This Row],[2023]]),0) -> -0.76676264 | M28: =Table7[[#This Row],[YoY growth]]-Table7[[#This Row],[Volume growth]] -> 6.5632112
B29: PAPILION (ArkPapers) | C29: 104.6663 | D29: 94.4256 | E29: 45.9485 | F29: 5728.6422 | G29: 5002.3734 | H29: 2228.919 | I29: =SUM(Table7[[#This Row],[Volume 2022]:[Volume YTD 2024]]) -> 12959.935 | J29: 245.0404 | K29: =IFERROR(((Table7[[#This Row],[2023]]-Table7[[#This Row],[2022]])/Table7[[#This Row],[2022]]),0) -> -0.097841426 | L29: =IFERROR(((Table7[[#This Row],[YTD 2024]]-Table7[[#This Row],[2023]])/Table7[[#This Row],[2023]]),0) -> -0.51338938 | M29: =Table7[[#This Row],[YoY growth]]-Table7[[#This Row],[Volume growth]] -> 0.41554795
B30: NIVEA (AlpineMeadow) | C30: 113.3088 | D30: 81.3137 | E30: 48.2974 | F30: 1483.433 | G30: 1045.7734 | H30: 598.3963 | I30: =SUM(Table7[[#This Row],[Volume 2022]:[Volume YTD 2024]]) -> 3127.6027 | J30: 242.9199 | K30: =IFERROR(((Table7[[#This Row],[2023]]-Table7[[#This Row],[2022]])/Table7[[#This Row],[2022]]),0) -> -0.28237083 | L30: =IFERROR(((Table7[[#This Row],[YTD 2024]]-Table7[[#This Row],[2023]])/Table7[[#This Row],[2023]]),0) -> -0.40603613 | M30: =Table7[[#This Row],[YoY growth]]-Table7[[#This Row],[Volume growth]] -> 0.1236653
B31: VIBELLE (REGINA TRADING LTD) | C31: 65.9287 | D31: 83.7331 | E31: 33.0609 | F31: 4636.9623 | G31: 5284.2041 | H31: 2040.6587 | I31: =SUM(Table7[[#This Row],[Volume 2022]:[Volume YTD 2024]]) -> 11961.825 | J31: 182.7227 | K31: =IFERROR(((Table7[[#This Row],[2023]]-Table7[[#This Row],[2022]])/Table7[[#This Row],[2022]]),0) -> 0.27005538 | L31: =IFERROR(((Table7[[#This Row],[YTD 2024]]-Table7[[#This Row],[2023]])/Table7[[#This Row],[2023]]),0) -> -0.60516331 | M31: =Table7[[#This Row],[YoY growth]]-Table7[[#This Row],[Volume growth]] -> 0.87521869
B32: ClearSight (ClearSight) | C32: 36.0259 | D32: 55.2294 | E32: 85.1398 | F32: 1024.5518 | G32: 1623.7086 | H32: 2439.0855 | I32: =SUM(Table7[[#This Row],[Volume 2022]:[Volume YTD 2024]]) -> 5087.3459 | J32: 176.3951 | K32: =IFERROR(((Table7[[#This Row],[2023]]-Table7[[#This Row],[2022]])/Table7[[#This Row],[2022]]),0) -> 0.53304706 | L32: =IFERROR(((Table7[[#This Row],[YTD 2024]]-Table7[[#This Row],[2023]])/Table7[[#This Row],[2023]]),0) -> 0.54156663 | M32: =Table7[[#This Row],[YoY growth]]-Table7[[#This Row],[Volume growth]] -> -0.0085195716
B33: HIPP (HIPP GMBH) | C33: 113.4864 | D33: 49.0462 | E33: 12.333 | F33: 2663.5762 | G33: 1050.6376 | H33: 244.3868 | I33: =SUM(Table7[[#This Row],[Volume 2022]:[Volume YTD 2024]]) -> 3958.6006 | J33: 174.8656 | K33: =IFERROR(((Table7[[#This Row],[2023]]-Table7[[#This Row],[2022]])/Table7[[#This Row],[2022]]),0) -> -0.5678231 | L33: =IFERROR(((Table7[[#This Row],[YTD 2024]]-Table7[[#This Row],[2023]])/Table7[[#This Row],[2023]]),0) -> -0.74854321 | M33: =Table7[[#This Row],[YoY growth]]-Table7[[#This Row],[Volume growth]] -> 0.18072011
B34: WIPEST (MORS COSMETICS) | C34: 14.5854 | D34: 84.6606 | E34: 67.9348 | F34: 930.2351 | G34: 4606.9654 | H34: 3467.3735 | I34: =SUM(Table7[[#This Row],[Volume 2022]:[Volume YTD 2024]]) -> 9004.574 | J34: 167.1808 | K34: =IFERROR(((Table7[[#This Row],[2023]]-Table7[[#This Row],[2022]])/Table7[[#This Row],[2022]]),0) -> 4.8044757 | L34: =IFERROR(((Table7[[#This Row],[YTD 2024]]-Table7[[#This Row],[2023]])/Table7[[#This Row],[2023]]),0) -> -0.19756297 | M34: =Table7[[#This Row],[YoY growth]]-Table7[[#This Row],[Volume growth]] -> 5.0020387
B35: GIAN (SCK ZETA COMPANY) | C35: 26.3474 | D35: 72.5916 | E35: 62.0075 | F35: 920.468 | G35: 3084.2016 | H35: 2719.9431 | I35: =SUM(Table7[[#This Row],[Volume 2022]:[Volume YTD 2024]]) -> 6724.6127 | J35: 160.9465 | K35: =IFERROR(((Table7[[#This Row],[2023]]-Table7[[#This Row],[2022]])/Table7[[#This Row],[2022]]),0) -> 1.7551713 | L35: =IFERROR(((Table7[[#This Row],[YTD 2024]]-Table7[[#This Row],[2023]])/Table7[[#This Row],[2023]]),0) -> -0.14580337 | M35: =Table7[[#This Row],[YoY growth]]-Table7[[#This Row],[Volume growth]] -> 1.9009747
B36: PEPINO (SEVIMLER) | C36: 55.7838 | D36: 57.8069 | E36: 19.8501 | F36: 3648.0402 | G36: 4041.2568 | H36: 1253.7541 | I36: =SUM(Table7[[#This Row],[Volume 2022]:[Volume YTD 2024]]) -> 8943.0511 | J36: 133.4408 | K36: =IFERROR(((Table7[[#This Row],[2023]]-Table7[[#This Row],[2022]])/Table7[[#This Row],[2022]]),0) -> 0.036266801 | L36: =IFERROR(((Table7[[#This Row],[YTD 2024]]-Table7[[#This Row],[2023]])/Table7[[#This Row],[2023]]),0) -> -0.65661366 | M36: =Table7[[#This Row],[YoY growth]]-Table7[[#This Row],[Volume growth]] -> 0.69288046
B37: PONKY (GULSAH KOZMETIK) | C37: 76.4723 | D37: 36.3665 | E37: 17.4222 | F37: 3099.3414 | G37: 1512.1391 | H37: 684.8154 | I37: =SUM(Table7[[#This Row],[Volume 2022]:[Volume YTD 2024]]) -> 5296.2959 | J37: 130.261 | K37: =IFERROR(((Table7[[#This Row],[2023]]-Table7[[#This Row],[2022]])/Table7[[#This Row],[2022]]),0) -> -0.52444872 | L37: =IFERROR(((Table7[[#This Row],[YTD 2024]]-Table7[[#This Row],[2023]])/Table7[[#This Row],[2023]]),0) -> -0.52092723 | M37: =Table7[[#This Row],[YoY growth]]-Table7[[#This Row],[Volume growth]] -> -0.003521495
B38: ALVESTA (SWORDSON LTD) | C38: 54.9888 | D38: 43.2233 | E38: 24.4581 | F38: 1994.8981 | G38: 1640.5911 | H38: 925.6536 | I38: =SUM(Table7[[#This Row],[Volume 2022]:[Volume YTD 2024]]) -> 4561.1428 | J38: 122.6702 | K38: =IFERROR(((Table7[[#This Row],[2023]]-Table7[[#This Row],[2022]])/Table7[[#This Row],[2022]]),0) -> -0.21396175 | L38: =IFERROR(((Table7[[#This Row],[YTD 2024]]-Table7[[#This Row],[2023]])/Table7[[#This Row],[2023]]),0) -> -0.43414547 | M38: =Table7[[#This Row],[YoY growth]]-Table7[[#This Row],[Volume growth]] -> 0.22018372
... B165: BAMBINO (ULTRA COSMETICS) | C165: 0 | D165: 0 | E165: 0 | F165: 0 | G165: 0 | H165: 0 | I165: =SUM(Table7[[#This Row],[Volume 2022]:[Volume YTD 2024]]) -> 0 | J165: 0 | K165: =IFERROR(((Table7[[#This Row],[2023]]-Table7[[#This Row],[2022]])/Table7[[#This Row],[2022]]),0) -> 0 | L165: =IFERROR(((Table7[[#This Row],[YTD 2024]]-Table7[[#This Row],[2023]])/Table7[[#This Row],[2023]]),0) -> 0 | M165: =Table7[[#This Row],[YoY growth]]-Table7[[#This Row],[Volume growth]] -> 0

Sheet pivot brand
A1: PACKAGE TYPE | B1: All
A2: PROTECTION / CARE | B2: All | D2: Sales performance report (Brand)
B4: Sum of 2022 | C4: Sum of 2023 | D4: Sum of YTD 2024 | E4: Sum of Total Value
A5: BABY CREMA (VigaLife) | B5: 3341.5013 | C5: 3428.0437 | D5: 1852.1969 | E5: 8621.7419
A6: PAMPERS (PROCTER & GAMBLE) | B6: 1818.1666 | C6: 2101.6939 | D6: 1233.5607 | E6: 5153.4212
A7: LINDY (Intelligent Initiative) | B7: 511.7809 | C7: 507.3048 | D7: 295.7138 | E7: 1314.7995
A8: EVENT (AxisOn Group) | B8: 471.6447 | C8: 448.0015 | D8: 276.1403 | E8: 1195.7865
A9: LARA (LARA KOZMETIK) | B9: 394.4622 | C9: 406.9338 | D9: 320.2154 | E9: 1121.6114
A10: Grand Total | B10: 6537.5557 | C10: 6891.9777 | D10: 3977.8271 | E10: 17407.361
A18: Row Labels | B18: Sum of Volume 2022 | C18: Sum of Volume 2023 | D18: Sum of Volume YTD 2024 | E18: Sum of Total Value | F18: Sum of Total Volume
A19: BABY CREMA (VigaLife) | B19: 125970.25 | C19: 127615.61 | D19: 64977.618 | E19: 8621.7419 | F19: 318563.48
A20: PAMPERS (PROCTER & GAMBLE) | B20: 45975.839 | C20: 53803.039 | D20: 29897.358 | E20: 5153.4212 | F20: 129676.24
A21: LINDY (Intelligent Initiative) | B21: 23199.702 | C21: 21680.539 | D21: 11434.484 | E21: 1314.7995 | F21: 56314.725
A22: EVENT (AxisOn Group) | B22: 13724.156 | C22: 13181.351 | D22: 8823.5241 | E22: 1195.7865 | F22: 35729.032
A23: LARA (LARA KOZMETIK) | B23: 18966.536 | C23: 19594.109 | D23: 15751.087 | E23: 1121.6114 | F23: 54311.731
A24: Grand Total | B24: 227836.48 | C24: 235874.65 | D24: 130884.07 | E24: 17407.361 | F24: 594595.21

Sheet productdetails
B1: Performance report (By Product) | E1: Growth Metrics | F1: Value ( in $1000) | I1: Volume (in 1000) | L1: Price Impact = | M1: Value growth - Volume growth | P1: Price Validation
F2: YoY Growth | G2: =((G3-F3)/F3) -> 0.032341622 | H2: =((H3-G3)/G3) -> -0.46405413 | I2: Volume YoY | J2: =((J3-I3)/I3) -> -0.0055203387 | K2: =((K3-J3)/J3) -> -0.49415464 | L2: Price Impact | M2: =G2-J2 -> 0.037861961 | N2: =H2-K2 -> 0.030100506 | P2: Price Impact | Q2: =((Q3-P3)/P3) -> 0.038072132 | R2: =((R3-Q3)/Q3) -> 0.059505352
E3: Freshclean (official data) | F3: 31416.343 | G3: 32432.398 | H3: 17382.01 | I3: 1194607.9 | J3: 1188013.2 | K3: 600950.98 | L3: Derived Calculation | P3: =F3/I3 -> 0.026298457 | Q3: =G3/J3 -> 0.027299695 | R3: =H3/K3 -> 0.028924173
B5: MANUFACTURER2 | C5: BRAND | D5: Company | E5: PRODUCT | F5: Package Type | G5: Protection/Care | H5: Package Size | I5: 2022 | J5: 2023 | K5: YTD 2024 | L5: Volume 2022 | M5: Volume 2023 | N5: Volume YTD 2024 | O5: Total Value | P5: YoY growth | Q5: Volume growth | R5: Price Growth | S5: mini value trend line
B6: Nova Garbagnate | C6: BABY 2000 | D6: Nova Garbagnate | E6: BABY2000 CAMOMILLA W 20 BAG ABA SRL | F6: BAGS | G6: WITHOUT EXTRA PROTECTCARE INDICATION | H6: 20 | I6: 1.935 | J6: 0.624 | K6: 0 | L6: 24.8229 | M6: 9.4086 | N6: 0 | O6: =SUM(Table1[[#This Row],[2022]:[YTD 2024]]) -> 2.559 | P6: =IFERROR(((Table1[[#This Row],[2023]]-Table1[[#This Row],[2022]])/Table1[[#This Row],[2022]]),0) -> -0.67751938 | Q6: =IFERROR(((Table1[[#This Row],[Volume 2023]]-Table1[[#This Row],[Volume 2022]])/Table1[[#This Row],[Volume 2022]]),0) -> -0.62097096 | R6: =Table1[[#This Row],[YoY growth]]-Table1[[#This Row],[Volume growth]] -> -0.056548422
B7: BeneCare | C7: BAMBO | D7: BeneCare | E7: BAMBO NATURE W 10 BAG | F7: BAGS | G7: WITHOUT EXTRA PROTECTCARE INDICATION | H7: 10 | I7: 0 | J7: 0 | K7: 0 | L7: 0 | M7: 0 | N7: 0 | O7: =SUM(Table1[[#This Row],[2022]:[YTD 2024]]) -> 0 | P7: =IFERROR(((Table1[[#This Row],[2023]]-Table1[[#This Row],[2022]])/Table1[[#This Row],[2022]]),0) -> 0 | Q7: =IFERROR(((Table1[[#This Row],[Volume 2023]]-Table1[[#This Row],[Volume 2022]])/Table1[[#This Row],[Volume 2022]]),0) -> 0 | R7: =Table1[[#This Row],[YoY growth]]-Table1[[#This Row],[Volume growth]] -> 0
B8: BeneCare | C8: BAMBO | D8: BeneCare | E8: BAMBO NATURE W 50 BAG | F8: BAGS | G8: WITHOUT EXTRA PROTECTCARE INDICATION | H8: 50 | I8: 0 | J8: 0 | K8: 0 | L8: 0 | M8: 0 | N8: 0 | O8: =SUM(Table1[[#This Row],[2022]:[YTD 2024]]) -> 0 | P8: =IFERROR(((Table1[[#This Row],[2023]]-Table1[[#This Row],[2022]])/Table1[[#This Row],[2022]]),0) -> 0 | Q8: =IFERROR(((Table1[[#This Row],[Volume 2023]]-Table1[[#This Row],[Volume 2022]])/Table1[[#This Row],[Volume 2022]]),0) -> 0 | R8: =Table1[[#This Row],[YoY growth]]-Table1[[#This Row],[Volume growth]] -> 0
B9: BeneCare | C9: BAMBO | D9: BeneCare | E9: BAMBO NATURE 0%PERFUME W 80 BAG | F9: BAGS | G9: WITHOUT EXTRA PROTECTCARE INDICATION | H9: 80 | I9: 0 | J9: 0 | K9: 0 | L9: 0 | M9: 0 | N9: 0 | O9: =SUM(Table1[[#This Row],[2022]:[YTD 2024]]) -> 0 | P9: =IFERROR(((Table1[[#This Row],[2023]]-Table1[[#This Row],[2022]])/Table1[[#This Row],[2022]]),0) -> 0 | Q9: =IFERROR(((Table1[[#This Row],[Volume 2023]]-Table1[[#This Row],[Volume 2022]])/Table1[[#This Row],[Volume 2022]]),0) -> 0 | R9: =Table1[[#This Row],[YoY growth]]-Table1[[#This Row],[Volume growth]] -> 0
B10: BeneCare | C10: BAMBO | D10: BeneCare | E10: BAMBO NATURE W 80 BAG KAPAK | F10: BAGS | G10: WITHOUT EXTRA PROTECTCARE INDICATION | H10: 80 | I10: 0.0109 | J10: 0 | K10: 0 | L10: 0.16 | M10: 0 | N10: 0 | O10: =SUM(Table1[[#This Row],[2022]:[YTD 2024]]) -> 0.0109 | P10: =IFERROR(((Table1[[#This Row],[2023]]-Table1[[#This Row],[2022]])/Table1[[#This Row],[2022]]),0) -> -1 | Q10: =IFERROR(((Table1[[#This Row],[Volume 2023]]-Table1[[#This Row],[Volume 2022]])/Table1[[#This Row],[Volume 2022]]),0) -> -1 | R10: =Table1[[#This Row],[YoY growth]]-Table1[[#This Row],[Volume growth]] -> 0
B11: VigaLife | C11: BABY CREMA | D11: VigaLife | E11: BABY CREMA PLAY TIME CAMOMILE W 100 PINK | F11: BAGS | G11: PH BALANCED | H11: 100 | I11: 81.4674 | J11: 92.903 | K11: 52.5119 | L11: 2980.7043 | M11: 3415.3554 | N11: 1823.0734 | O11: =SUM(Table1[[#This Row],[2022]:[YTD 2024]]) -> 226.8823 | P11: =IFERROR(((Table1[[#This Row],[2023]]-Table1[[#This Row],[2022]])/Table1[[#This Row],[2022]]),0) -> 0.14037026 | Q11: =IFERROR(((Table1[[#This Row],[Volume 2023]]-Table1[[#This Row],[Volume 2022]])/Table1[[#This Row],[Volume 2022]]),0) -> 0.14582161 | R11: =Table1[[#This Row],[YoY growth]]-Table1[[#This Row],[Volume growth]] -> -0.0054513515
B12: VigaLife | C12: BABY CREMA | D12: VigaLife | E12: BABYCREMA PLAYTIME CAMOMIL W 72 BAG KAPA | F12: BAGS | G12: PH BALANCED | H12: 72 | I12: 1663.8369 | J12: 1815.6597 | K12: 1049.2486 | L12: 62012.673 | M12: 68679.966 | N12: 37856.882 | O12: =SUM(Table1[[#This Row],[2022]:[YTD 2024]]) -> 4528.7452 | P12: =IFERROR(((Table1[[#This Row],[2023]]-Table1[[#This Row],[2022]])/Table1[[#This Row],[2022]]),0) -> 0.091248607 | Q12: =IFERROR(((Table1[[#This Row],[Volume 2023]]-Table1[[#This Row],[Volume 2022]])/Table1[[#This Row],[Volume 2022]]),0) -> 0.10751502 | R12: =Table1[[#This Row],[YoY growth]]-Table1[[#This Row],[Volume growth]] -> -0.016266409
